Workbook
Name CompetenciasDisponiveis: OFFSET('Resumo Usinas (Histórico)'!$H$5,0,0,COUNTIFS('Resumo Usinas (Histórico)'!$H$5:$H$500,"<>"),1)

Sheet Instruções
A1: Instruções de Preenchimento — Controle GD TRI STAR ONE SCP
A2: Leia esta aba antes de lançar os dados do mês. A planilha é cumulativa: nunca apague ou sobrescreva competências já lançadas.
A4: 1. Rotina mensal — o que fazer a cada novo demonstrativo
A5: • Para cada usina, abra o novo 'Demonstrativo de Faturamento' (Neoenergia/Cosern) do mês.
A6: • Na aba 'Resumo Usinas (Histórico)': adicione UMA NOVA LINHA por usina (nunca sobrescreva a linha do mês anterior) com a Competência do mês e os valores do bloco 'Resumo de Saldo de Crédito' do relatório (Total Injetado, Total Compensado, Saldo Acumulado, Próximo Saldo a Expirar, Ciclo de Faturamento a Expirar, Total de Créditos Expirados).
A7: • Na aba 'Dados Mensais (Histórico)': adicione uma NOVA LINHA por código de cliente (injetor e beneficiários) com a Competência e os valores de 'Dados dos Últimos 13 Meses' (Energia Consumida, Energia Injetada, Energ. Exc. Alocada, KWh Compensado, Energia Faturada, Crédito).
A8: • Confira a aba 'Rateio de Crédito': só precisa mexer nela se o percentual de rateio contratual entre injetor e beneficiários tiver mudado. Se mudar, atualize o percentual e a data em 'Vigente desde'.
A9: • Abra a aba 'Dashboard' — ela é 100% automática e vai puxar sozinha a competência mais recente de cada usina, o saldo atual e o rateio por beneficiário.
A11: 2. Onde inserir cada dado (mapa das abas)
A12: • Dashboard — não digitar nada aqui. Todas as células são fórmulas que leem as outras abas.
A13: • Resumo Usinas (Histórico) — inserir aqui: 1 linha por usina a cada mês (dados do bloco 'Resumo de Saldo de Crédito').
A14: • Rateio de Crédito — inserir/editar aqui: percentual de rateio por código beneficiário (raramente muda).
... A33: • A aba 'Auxiliar (Não Editar)' alimenta o gráfico de linha automaticamente — não digite nada nela.

Sheet Preco (R$ x KWh)
B1: FATURA COSERN | C1: CONTRATO CLIENTE
A2: Mês | B2: Preco (R$ x KWh) | C2: Preco (R$ x KWh)
A3: 45505 | B3: 0.94362878 | C3: =B3*0.7 -> 0.66054015
A4: 45536 | B4: 0.94995059 | C4: =B4*0.7 -> 0.66496541
A5: 45566 | B5: 0.95706369 | C5: =B5*0.7 -> 0.66994458
A6: 45597 | B6: 0.95655929 | C6: =B6*0.7 -> 0.6695915
A7: 45627 | B7: 0.95686187 | C7: =B7*0.7 -> 0.66980331
A8: 45658 | B8: 0.94304042 | C8: =B8*0.7 -> 0.66012829
A9: 45689 | B9: 0.97621321 | C9: =B9*0.7 -> 0.68334925
A10: 45717 | B10: 0.95797297 | C10: =B10*0.7 -> 0.67058108
A11: 45748 | B11: 0.98119725 | C11: =B11*0.7 -> 0.68683807
A12: 45778 | B12: 0.98489525 | C12: =B12*0.7 -> 0.68942667
A13: 45809 | B13: =0.56795504+0.40914819 -> 0.97710323 | C13: =B13*0.7 -> 0.68397226
A14: 45839 | B14: =0.57858977+0.41680933 -> 0.9953991 | C14: =B14*0.7 -> 0.69677937
A15: 45870 | B15: =0.5770462+0.41569736 -> 0.99274356 | C15: =B15*0.7 -> 0.69492049
A16: 45901 | B16: =0.57222222+0.41222222 -> 0.98444444 | C16: =B16*0.7 -> 0.68911111
A17: 45931 | B17: =0.57723099+0.41583048 -> 0.99306147 | C17: =B17*0.7 -> 0.69514303
A18: 45962 | B18: =0.58283035+0.41986419 -> 1.0026945 | C18: =B18*0.7 -> 0.70188618
A19: 45992 | B19: =0.58283035+0.41986419 -> 1.0026945 | C19: =B19*0.7 -> 0.70188618
A20: 46023 | B20: =0.5761854+0.41507725 -> 0.99126265 | C20: =B20*0.7 -> 0.69388385
A21: 46054 | B21: =0.57355748+0.41318413 -> 0.98674161 | C21: =B21*0.7 -> 0.69071913
A22: 46082 | B22: =0.57575596+0.41476788 -> 0.99052384 | C22: =B22*0.7 -> 0.69336669
A23: 46113 | B23: =0.57337503+0.41305269 -> 0.98642772 | C23: =B23*0.7 -> 0.6904994
A24: 46143 | B24: =0.6177727+0.40735685 -> 1.0251295 | C24: =B24*0.7 -> 0.71759068
A25: 46174 | B25: =0.64164094+0.39033734 -> 1.0319783 | C25: =B25*0.7 -> 0.7223848
A26: 46204 | B26: =0.64164094+0.39033734 -> 1.0319783 | C26: =B26*0.7 -> 0.7223848
A27: 46235 | B27: =0.64335253+0.39137857 -> 1.0347311 | C27: =B27*0.7 -> 0.72431177
A28: 46266 | B28: =0.64966059+0.39521603 -> 1.0448766 | C28: =B28*0.7 -> 0.73141363
A29: 46296 | B29: =0.63946335+0.38901262 -> 1.028476 | C29: =B29*0.7 -> 0.71993318
A30: 46327 | C30: =B30*0.7 -> 0
A31: 46357 | C31: =B31*0.7 -> 0
A32: 46388 | C32: =B32*0.7 -> 0
A33: 46419 | C33: =B33*0.7 -> 0
A34: 46447 | C34: =B34*0.7 -> 0
A35: 46478 | C35: =B35*0.7 -> 0
A36: 46508 | C36: =B36*0.7 -> 0
A37: 46539 | C37: =B37*0.7 -> 0
A38: 46569 | C38: =B38*0.7 -> 0
A39: 46600 | C39: =B39*0.7 -> 0
A40: 46631 | C40: =B40*0.7 -> 0
...

Sheet Dashboard
B1: Dashboard — Controle de Geração Distribuída TRI STAR ONE SCP
B2: Escolha a competência abaixo para ver o saldo de crédito acumulado e o rateio por beneficiário até aquele mês
B4: Competência de Referência (escolha): | E4: 46296 | G4: Última competência disponível: | I4: =TEXT(_xlfn.MAXIFS('Resumo Usinas (Histórico)'!$H$5:$H$500,'Resumo Usinas (Histórico)'!$J$5:$J$500,"<>"),"mmm/AAAA") -> out/2026
B6: Total Injetado até Competência referenciada (kWh) | F6: Total Alocado a Beneficiários (kWh) | I6: Usinas Ativas / Em Construção
B7: =G22 -> 49510 | F7: =H37 -> 49510 | I7: 4 / 8
B10: Total Injetado por Usina — Acumulado até a Competência Escolhida
A11: concatenar | B11: Usina / Cliente Gerador | C11: Cód. Interno | D11: Código Injetor | E11: Competência Considerada | F11: Potência (kWp) | G11: Total Injetado (kWh) | H11: % Alocado a Beneficiários | I11: Situação
A12: =CONCATENATE(D12,E12) -> 703010264346296 | B12: ARCO IRIS ADMINISTRADORA | C12: TRI007 | D12: 7030102643 | E12: =IF(COUNTIFS('Resumo Usinas (Histórico)'!$C$5:$C$500,D12,'Resumo Usinas (Histórico)'!$H$5:$H$500,"<="&$E$4,'Resumo Usinas (Histórico)'!$J$5:$J$500,"<>")=0,"Sem dados",_xlfn.MAXIFS('Resumo Usinas (Histórico)'!$H$5:$H$500,'Resumo Usinas (Histórico)'!$C$5:$C$500,D12,'Resumo Usinas (Histórico)'!$H$5:$H$500,"<="&$E$4)) -> 46296 | F12: =IF(E12="Sem dados","-",IFERROR(INDEX('Resumo Usinas (Histórico)'!$E$5:$E$500,MATCH(A12,'Resumo Usinas (Histórico)'!$A$5:$A$500,0)),"-")) -> 60 | G12: =IF(E12="Sem dados","-",IFERROR(SUMIFS('Resumo Usinas (Histórico)'!$J$5:$J$500,'Resumo Usinas (Histórico)'!$C$5:$C$500,D12,'Resumo Usinas (Histórico)'!$H$5:$H$500,E12),"-")) -> 4368 | H12: =IFERROR(SUMIFS('Rateio de Crédito'!$F$5:$F$151,'Rateio de Crédito'!$B$5:$B$151,D12,'Rateio de Crédito'!$E$5:$E$151,"<>Injetor (Gerador)"),0) -> 1 | I12: Rateado para 1 UC externa — beneficiário sem consumo faturado (verificar UC 7001017068)
A13: =CONCATENATE(D13,E13) -> 703086904946296 | B13: SAF HOSPEDAGENS | C13: TRI008 | D13: 7030869049 | E13: =IF(COUNTIFS('Resumo Usinas (Histórico)'!$C$5:$C$500,D13,'Resumo Usinas (Histórico)'!$H$5:$H$500,"<="&$E$4,'Resumo Usinas (Histórico)'!$J$5:$J$500,"<>")=0,"Sem dados",_xlfn.MAXIFS('Resumo Usinas (Histórico)'!$H$5:$H$500,'Resumo Usinas (Histórico)'!$C$5:$C$500,D13,'Resumo Usinas (Histórico)'!$H$5:$H$500,"<="&$E$4)) -> 46296 | F13: =IF(E13="Sem dados","-",IFERROR(INDEX('Resumo Usinas (Histórico)'!$E$5:$E$500,MATCH(A13,'Resumo Usinas (Histórico)'!$A$5:$A$500,0)),"-")) -> 60 | G13: =IF(E13="Sem dados","-",IFERROR(SUMIFS('Resumo Usinas (Histórico)'!$J$5:$J$500,'Resumo Usinas (Histórico)'!$C$5:$C$500,D13,'Resumo Usinas (Histórico)'!$H$5:$H$500,E13),"-")) -> 15158 | H13: =IFERROR(SUMIFS('Rateio de Crédito'!$F$5:$F$151,'Rateio de Crédito'!$B$5:$B$151,D13,'Rateio de Crédito'!$E$5:$E$151,"<>Injetor (Gerador)"),0) -> 1 | I13: Autoconsumo remoto — 100% do crédito retido pelo próprio injetor
A14: =CONCATENATE(D14,E14) -> 703086906546266 | B14: JM EMPREENDIMENTOS | C14: TRI002 | D14: 7030869065 | E14: =IF(COUNTIFS('Resumo Usinas (Histórico)'!$C$5:$C$500,D14,'Resumo Usinas (Histórico)'!$H$5:$H$500,"<="&$E$4,'Resumo Usinas (Histórico)'!$J$5:$J$500,"<>")=0,"Sem dados",_xlfn.MAXIFS('Resumo Usinas (Histórico)'!$H$5:$H$500,'Resumo Usinas (Histórico)'!$C$5:$C$500,D14,'Resumo Usinas (Histórico)'!$H$5:$H$500,"<="&$E$4)) -> 46266 | F14: =IF(E14="Sem dados","-",IFERROR(INDEX('Resumo Usinas (Histórico)'!$E$5:$E$500,MATCH(A14,'Resumo Usinas (Histórico)'!$A$5:$A$500,0)),"-")) -> 60 | G14: =IF(E14="Sem dados","-",IFERROR(SUMIFS('Resumo Usinas (Histórico)'!$J$5:$J$500,'Resumo Usinas (Histórico)'!$C$5:$C$500,D14,'Resumo Usinas (Histórico)'!$H$5:$H$500,E14),"-")) -> 7136 | H14: =IFERROR(SUMIFS('Rateio de Crédito'!$F$5:$F$151,'Rateio de Crédito'!$B$5:$B$151,D14,'Rateio de Crédito'!$E$5:$E$151,"<>Injetor (Gerador)"),0) -> 1 | I14: Autoconsumo remoto — 100% do crédito retido pelo próprio injetor
A15: =CONCATENATE(D15,E15) -> 703086929446296 | B15: SOMBRA FLORESTA | C15: TRI001 | D15: 7030869294 | E15: =IF(COUNTIFS('Resumo Usinas (Histórico)'!$C$5:$C$500,D15,'Resumo Usinas (Histórico)'!$H$5:$H$500,"<="&$E$4,'Resumo Usinas (Histórico)'!$J$5:$J$500,"<>")=0,"Sem dados",_xlfn.MAXIFS('Resumo Usinas (Histórico)'!$H$5:$H$500,'Resumo Usinas (Histórico)'!$C$5:$C$500,D15,'Resumo Usinas (Histórico)'!$H$5:$H$500,"<="&$E$4)) -> 46296 | F15: =IF(E15="Sem dados","-",IFERROR(INDEX('Resumo Usinas (Histórico)'!$E$5:$E$500,MATCH(A15,'Resumo Usinas (Histórico)'!$A$5:$A$500,0)),"-")) -> 60 | G15: =IF(E15="Sem dados","-",IFERROR(SUMIFS('Resumo Usinas (Histórico)'!$J$5:$J$500,'Resumo Usinas (Histórico)'!$C$5:$C$500,D15,'Resumo Usinas (Histórico)'!$H$5:$H$500,E15),"-")) -> 19215 | H15: =IFERROR(SUMIFS('Rateio de Crédito'!$F$5:$F$151,'Rateio de Crédito'!$B$5:$B$151,D15,'Rateio de Crédito'!$E$5:$E$151,"<>Injetor (Gerador)"),0) -> 1 | I15: Rateado para 4 UCs externas
A16: =CONCATENATE(D16,E16) -> 703175443146296 | B16: ARCO IRIS ADMINISTRADORA | C16: TRI003 | D16: 7031754431 | E16: =IF(COUNTIFS('Resumo Usinas (Histórico)'!$C$5:$C$500,D16,'Resumo Usinas (Histórico)'!$H$5:$H$500,"<="&$E$4,'Resumo Usinas (Histórico)'!$J$5:$J$500,"<>")=0,"Sem dados",_xlfn.MAXIFS('Resumo Usinas (Histórico)'!$H$5:$H$500,'Resumo Usinas (Histórico)'!$C$5:$C$500,D16,'Resumo Usinas (Histórico)'!$H$5:$H$500,"<="&$E$4)) -> 46296 | F16: =IF(E16="Sem dados","-",IFERROR(INDEX('Resumo Usinas (Histórico)'!$E$5:$E$500,MATCH(A16,'Resumo Usinas (Histórico)'!$A$5:$A$500,0)),"-")) -> 33 | G16: =IF(E16="Sem dados","-",IFERROR(SUMIFS('Resumo Usinas (Histórico)'!$J$5:$J$500,'Resumo Usinas (Histórico)'!$C$5:$C$500,D16,'Resumo Usinas (Histórico)'!$H$5:$H$500,E16),"-")) -> 3633 | H16: =IFERROR(SUMIFS('Rateio de Crédito'!$F$5:$F$151,'Rateio de Crédito'!$B$5:$B$151,D16,'Rateio de Crédito'!$E$5:$E$151,"<>Injetor (Gerador)"),0) -> 1 | I16: Rateado para 1 UC externa
A17: =CONCATENATE(D17,E17) -> A DEFINIR-06Sem dados | B17: USINA EM CONSTRUÇÃO 06 | D17: A DEFINIR-06 | E17: =IF(COUNTIFS('Resumo Usinas (Histórico)'!$C$5:$C$500,D17,'Resumo Usinas (Histórico)'!$H$5:$H$500,"<="&$E$4,'Resumo Usinas (Histórico)'!$J$5:$J$500,"<>")=0,"Sem dados",_xlfn.MAXIFS('Resumo Usinas (Histórico)'!$H$5:$H$500,'Resumo Usinas (Histórico)'!$C$5:$C$500,D17,'Resumo Usinas (Histórico)'!$H$5:$H$500,"<="&$E$4)) -> Sem dados | F17: =IF(E17="Sem dados","-",IFERROR(INDEX('Resumo Usinas (Histórico)'!$E$5:$E$500,MATCH(D17,'Resumo Usinas (Histórico)'!$C$5:$C$500,0)),"-")) -> - | G17: =IF(E17="Sem dados","-",IFERROR(SUMIFS('Resumo Usinas (Histórico)'!$L$5:$L$500,'Resumo Usinas (Histórico)'!$C$5:$C$500,D17,'Resumo Usinas (Histórico)'!$H$5:$H$500,E17),"-")) -> - | H17: =IFERROR(SUMIFS('Rateio de Crédito'!$F$5:$F$151,'Rateio de Crédito'!$B$5:$B$151,D17,'Rateio de Crédito'!$E$5:$E$151,"<>Injetor (Gerador)"),0) -> 0 | I17: Em construção — aguardando entrada em operação
A18: =CONCATENATE(D18,E18) -> A DEFINIR-07Sem dados | B18: USINA EM CONSTRUÇÃO 07 | D18: A DEFINIR-07 | E18: =IF(COUNTIFS('Resumo Usinas (Histórico)'!$C$5:$C$500,D18,'Resumo Usinas (Histórico)'!$H$5:$H$500,"<="&$E$4,'Resumo Usinas (Histórico)'!$J$5:$J$500,"<>")=0,"Sem dados",_xlfn.MAXIFS('Resumo Usinas (Histórico)'!$H$5:$H$500,'Resumo Usinas (Histórico)'!$C$5:$C$500,D18,'Resumo Usinas (Histórico)'!$H$5:$H$500,"<="&$E$4)) -> Sem dados | F18: =IF(E18="Sem dados","-",IFERROR(INDEX('Resumo Usinas (Histórico)'!$E$5:$E$500,MATCH(D18,'Resumo Usinas (Histórico)'!$C$5:$C$500,0)),"-")) -> - | G18: =IF(E18="Sem dados","-",IFERROR(SUMIFS('Resumo Usinas (Histórico)'!$L$5:$L$500,'Resumo Usinas (Histórico)'!$C$5:$C$500,D18,'Resumo Usinas (Histórico)'!$H$5:$H$500,E18),"-")) -> - | H18: =IFERROR(SUMIFS('Rateio de Crédito'!$F$5:$F$151,'Rateio de Crédito'!$B$5:$B$151,D18,'Rateio de Crédito'!$E$5:$E$151,"<>Injetor (Gerador)"),0) -> 0 | I18: Em construção — aguardando entrada em operação
A19: =CONCATENATE(D19,E19) -> A DEFINIR-08Sem dados | B19: USINA EM CONSTRUÇÃO 08 | D19: A DEFINIR-08 | E19: =IF(COUNTIFS('Resumo Usinas (Histórico)'!$C$5:$C$500,D19,'Resumo Usinas (Histórico)'!$H$5:$H$500,"<="&$E$4,'Resumo Usinas (Histórico)'!$J$5:$J$500,"<>")=0,"Sem dados",_xlfn.MAXIFS('Resumo Usinas (Histórico)'!$H$5:$H$500,'Resumo Usinas (Histórico)'!$C$5:$C$500,D19,'Resumo Usinas (Histórico)'!$H$5:$H$500,"<="&$E$4)) -> Sem dados | F19: =IF(E19="Sem dados","-",IFERROR(INDEX('Resumo Usinas (Histórico)'!$E$5:$E$500,MATCH(D19,'Resumo Usinas (Histórico)'!$C$5:$C$500,0)),"-")) -> - | G19: =IF(E19="Sem dados","-",IFERROR(SUMIFS('Resumo Usinas (Histórico)'!$L$5:$L$500,'Resumo Usinas (Histórico)'!$C$5:$C$500,D19,'Resumo Usinas (Histórico)'!$H$5:$H$500,E19),"-")) -> - | H19: =IFERROR(SUMIFS('Rateio de Crédito'!$F$5:$F$151,'Rateio de Crédito'!$B$5:$B$151,D19,'Rateio de Crédito'!$E$5:$E$151,"<>Injetor (Gerador)"),0) -> 0 | I19: Em construção — aguardando entrada em operação
A20: =CONCATENATE(D20,E20) -> A DEFINIR-09Sem dados | B20: USINA EM CONSTRUÇÃO 09 | D20: A DEFINIR-09 | E20: =IF(COUNTIFS('Resumo Usinas (Histórico)'!$C$5:$C$500,D20,'Resumo Usinas (Histórico)'!$H$5:$H$500,"<="&$E$4,'Resumo Usinas (Histórico)'!$J$5:$J$500,"<>")=0,"Sem dados",_xlfn.MAXIFS('Resumo Usinas (Histórico)'!$H$5:$H$500,'Resumo Usinas (Histórico)'!$C$5:$C$500,D20,'Resumo Usinas (Histórico)'!$H$5:$H$500,"<="&$E$4)) -> Sem dados | F20: =IF(E20="Sem dados","-",IFERROR(INDEX('Resumo Usinas (Histórico)'!$E$5:$E$500,MATCH(D20,'Resumo Usinas (Histórico)'!$C$5:$C$500,0)),"-")) -> - | G20: =IF(E20="Sem dados","-",IFERROR(SUMIFS('Resumo Usinas (Histórico)'!$L$5:$L$500,'Resumo Usinas (Histórico)'!$C$5:$C$500,D20,'Resumo Usinas (Histórico)'!$H$5:$H$500,E20),"-")) -> - | H20: =IFERROR(SUMIFS('Rateio de Crédito'!$F$5:$F$151,'Rateio de Crédito'!$B$5:$B$151,D20,'Rateio de Crédito'!$E$5:$E$151,"<>Injetor (Gerador)"),0) -> 0 | I20: Em construção — aguardando entrada em operação
A21: =CONCATENATE(D21,E21) -> A DEFINIR-10Sem dados | B21: USINA EM CONSTRUÇÃO 10 | D21: A DEFINIR-10 | E21: =IF(COUNTIFS('Resumo Usinas (Histórico)'!$C$5:$C$500,D21,'Resumo Usinas (Histórico)'!$H$5:$H$500,"<="&$E$4,'Resumo Usinas (Histórico)'!$J$5:$J$500,"<>")=0,"Sem dados",_xlfn.MAXIFS('Resumo Usinas (Histórico)'!$H$5:$H$500,'Resumo Usinas (Histórico)'!$C$5:$C$500,D21,'Resumo Usinas (Histórico)'!$H$5:$H$500,"<="&$E$4)) -> Sem dados | F21: =IF(E21="Sem dados","-",IFERROR(INDEX('Resumo Usinas (Histórico)'!$E$5:$E$500,MATCH(D21,'Resumo Usinas (Histórico)'!$C$5:$C$500,0)),"-")) -> - | G21: =IF(E21="Sem dados","-",IFERROR(SUMIFS('Resumo Usinas (Histórico)'!$L$5:$L$500,'Resumo Usinas (Histórico)'!$C$5:$C$500,D21,'Resumo Usinas (Histórico)'!$H$5:$H$500,E21),"-")) -> - | H21: =IFERROR(SUMIFS('Rateio de Crédito'!$F$5:$F$151,'Rateio de Crédito'!$B$5:$B$151,D21,'Rateio de Crédito'!$E$5:$E$151,"<>Injetor (Gerador)"),0) -> 0 | I21: Em construção — aguardando entrada em operação
B22: TOTAL | G22: =SUM(G12:G21) -> 49510
B25: Rateio do Saldo de Crédito por Unidade Beneficiária
B26: Usina | C26: Cód. Interno | D26: Código Injetor | E26: Código Beneficiário | F26: Papel | G26: % Rateio | H26: Saldo Alocado (kWh) | I26: Vigente desde
B27: ARCO IRIS ADMINISTRADORA | C27: TRI007 | D27: 7030102643 | E27: 7001017068 | F27: Beneficiário | G27: =VLOOKUP(E27,'Rateio de Crédito'!C:F,4,0) -> 1 | H27: =IFERROR(G27*$G$12,"-") -> 4368 | I27: =IF(ISBLANK('Rateio de Crédito'!G6),"-",'Rateio de Crédito'!G6) -> 46204
B28: SAF HOSPEDAGENS | C28: TRI008 | D28: 7030869049 | E28: 7030869049 | F28: Injetor e Beneficiário (autoconsumo) | G28: =VLOOKUP(E28,'Rateio de Crédito'!C:F,4,0) -> 1 | H28: =IFERROR(G28*$G$13,"-") -> 15158 | I28: =IF(ISBLANK('Rateio de Crédito'!G7),"-",'Rateio de Crédito'!G7) -> 46204
B29: JM EMPREENDIMENTOS | C29: TRI002 | D29: 7030869065 | E29: 7031138749 | F29: Beneficiário | G29: =VLOOKUP(E29,'Rateio de Crédito'!C:F,4,0) -> 1 | H29: =IFERROR(G29*$G$14,"-") -> 7136 | I29: =IF(ISBLANK('Rateio de Crédito'!G10),"-",'Rateio de Crédito'!G10) -> 46204
B30: SOMBRA FLORESTA | C30: TRI001 | D30: 7030869294 | E30: 7022476844 | F30: Beneficiário | G30: =VLOOKUP(E30,'Rateio de Crédito'!C:F,4,0) -> 0.25 | H30: =IFERROR(G30*$G$15,"-") -> 4803.75 | I30: =IF(ISBLANK('Rateio de Crédito'!G12),"-",'Rateio de Crédito'!G12) -> 46204
B31: SOMBRA FLORESTA | C31: TRI001 | D31: 7030869294 | E31: 7022476950 | F31: Beneficiário | G31: =VLOOKUP(E31,'Rateio de Crédito'!C:F,4,0) -> 0.25 | H31: =IFERROR(G31*$G$15,"-") -> 4803.75 | I31: =IF(ISBLANK('Rateio de Crédito'!G13),"-",'Rateio de Crédito'!G13) -> 46204
B32: SOMBRA FLORESTA | C32: TRI001 | D32: 7030869294 | E32: 7022546729 | F32: Beneficiário | G32: =VLOOKUP(E32,'Rateio de Crédito'!C:F,4,0) -> 0.25 | H32: =IFERROR(G32*$G$15,"-") -> 4803.75 | I32: =IF(ISBLANK('Rateio de Crédito'!G14),"-",'Rateio de Crédito'!G14) -> 46204
B33: SOMBRA FLORESTA | C33: TRI001 | D33: 7030869294 | E33: 7022546796 | F33: Beneficiário | G33: =VLOOKUP(E33,'Rateio de Crédito'!C:F,4,0) -> 0.25 | H33: =IFERROR(G33*$G$15,"-") -> 4803.75 | I33: =IF(ISBLANK('Rateio de Crédito'!G15),"-",'Rateio de Crédito'!G15) -> 46296
B34: ARCO IRIS ADMINISTRADORA | C34: TRI003 | D34: 7030102643 | E34: 7027595701 | F34: Beneficiário | G34: =VLOOKUP(E34,'Rateio de Crédito'!C:F,4,0) -> 1 | H34: =IFERROR(G34*$G$16,"-") -> 3633 | I34: =IF(ISBLANK('Rateio de Crédito'!G16),"-",'Rateio de Crédito'!G16) -> 46296
B35: USINA EM CONSTRUÇÃO 07 | C35: A DEFINIR-07 | D35: A DEFINIR-07 | H35: =IFERROR(G35*$G$18,"-") -> - | I35: =IF(ISBLANK('Rateio de Crédito'!G17),"-",'Rateio de Crédito'!G17) -> -
B36: USINA EM CONSTRUÇÃO 08 | C36: A DEFINIR-08 | D36: A DEFINIR-08 | H36: =IFERROR(G36*$G$19,"-") -> - | I36: =IF(ISBLANK('Rateio de Crédito'!G18),"-",'Rateio de Crédito'!G18) -> -
B37: TOTAL RATEADO | H37: =SUM(H27:H36) -> 49510
B39: Como funciona: escolha a competência na célula em vermelho acima. A Tabela A busca, para cada usina, o registro mais recente com data igual ou anterior à competência escolhida na aba 'Resumo Usinas (Histórico)'. A Tabela B multiplica esse saldo pelo percentual de rateio configurado na aba 'Rateio de Crédito'. Os gráficos abaixo também respeitam a competência escolhida (pizza) ou mostram a evolução completa do histórico (linha).

Sheet Faturamento (Não Editar)
A1: Série Histórica — Energia Injetada por Usina (gerado automaticamente)
A2: Não editar. Esta aba alimenta o gráfico de linha de energia injetada do Dashboard e é recalculada sozinha conforme novas competências são lançadas.
K3: VALOR DE COBRANÇA | P3: TOTAL | R3: Configurações - emissao NF:
K4: 7030102643 | L4: 7031754431 | M4: 7030869049 | N4: 7030869065 | O4: 7030869294 | R4: Cód. De tributação nacional: | S4: 990101 - serviço sem a incidência de ISSQN e ICMS
A5: Usina | B5: 7030102643 | C5: 7031754431 | D5: 7030869049 | E5: 7030869065 | F5: 7030869294 | K5: 06036746/0001-31 | L5: 06036746/0001-31 | M5: 05311448/0001-40 | N5: 07059083/0001-33 | O5: 05311448/0001-40 | R5: NBS: | S5: 1.1101.90.00 - arrendamento mercantil operacional ou locação de máquinas e equipamentos, sem operador, não classificado em subposições anteriores
A6: Competência | B6: ARCO-IRIS | C6: ARCO-IRIS | D6: SAF HOSPEDAGENS | E6: JM EMPREENDIMENTOS | F6: SOMBRA FLORESTA | H6: Preço R$/KWh | I6: Preço R$/KWh (-) 30% | K6: ARCO-IRIS | L6: ARCO-IRIS | M6: SAF HOSPEDAGENS | N6: JM EMPREENDIMENTOS | O6: SOMBRA FLORESTA | R6: Subtitem: | S6: 99.04.01 - Locação de Bens Móveis
A7: =_xlfn.MINIFS('Resumo Usinas (Histórico)'!$H$5:$H$500,'Resumo Usinas (Histórico)'!$J$5:$J$500,"<>") -> 46204 | B7: =IF(COUNTIFS('Dados Mensais (Histórico)'!$B$5:$B$521,B$5,'Dados Mensais (Histórico)'!$E$5:$E$521,$A7)=0,"",SUMIFS('Dados Mensais (Histórico)'!$J$5:$J$521,'Dados Mensais (Histórico)'!$B$5:$B$521,B$5,'Dados Mensais (Histórico)'!$E$5:$E$521,$A7)) -> 338 | C7: =IF(COUNTIFS('Dados Mensais (Histórico)'!$B$5:$B$521,C$5,'Dados Mensais (Histórico)'!$E$5:$E$521,$A7)=0,"",SUMIFS('Dados Mensais (Histórico)'!$J$5:$J$521,'Dados Mensais (Histórico)'!$B$5:$B$521,C$5,'Dados Mensais (Histórico)'!$E$5:$E$521,$A7)) | D7: =IF(COUNTIFS('Dados Mensais (Histórico)'!$B$5:$B$521,D$5,'Dados Mensais (Histórico)'!$E$5:$E$521,$A7)=0,"",SUMIFS('Dados Mensais (Histórico)'!$J$5:$J$521,'Dados Mensais (Histórico)'!$B$5:$B$521,D$5,'Dados Mensais (Histórico)'!$E$5:$E$521,$A7)) -> 875 | E7: =IF(COUNTIFS('Dados Mensais (Histórico)'!$B$5:$B$521,E$5,'Dados Mensais (Histórico)'!$E$5:$E$521,$A7)=0,"",SUMIFS('Dados Mensais (Histórico)'!$J$5:$J$521,'Dados Mensais (Histórico)'!$B$5:$B$521,E$5,'Dados Mensais (Histórico)'!$E$5:$E$521,$A7)) -> 1158 | F7: =IF(COUNTIFS('Dados Mensais (Histórico)'!$B$5:$B$521,F$5,'Dados Mensais (Histórico)'!$E$5:$E$521,$A7)=0,"",SUMIFS('Dados Mensais (Histórico)'!$J$5:$J$521,'Dados Mensais (Histórico)'!$B$5:$B$521,F$5,'Dados Mensais (Histórico)'!$E$5:$E$521,$A7)) -> 608 | H7: ='Preco (R$ x KWh)'!B26 -> 1.0319783 | I7: =H7*0.7 -> 0.7223848 | K7: =IF(B7="","",ROUND(B7*$I7,2)) -> 244.17 | L7: =IF(C7="","",ROUND(C7*$I7,2)) | M7: =IF(D7="","",ROUND(D7*$I7,2)) -> 632.09 | N7: =IF(E7="","",ROUND(E7*$I7,2)) -> 836.52 | O7: =IF(F7="","",ROUND(F7*$I7,2)) -> 439.21 | P7: =SUM(K7:O7) -> 2151.99
A8: =EDATE(A7,1) -> 46235 | B8: =IF(COUNTIFS('Dados Mensais (Histórico)'!$B$5:$B$521,B$5,'Dados Mensais (Histórico)'!$E$5:$E$521,$A8)=0,"",SUMIFS('Dados Mensais (Histórico)'!$J$5:$J$521,'Dados Mensais (Histórico)'!$B$5:$B$521,B$5,'Dados Mensais (Histórico)'!$E$5:$E$521,$A8)) -> 3425 | C8: =IF(COUNTIFS('Dados Mensais (Histórico)'!$B$5:$B$521,C$5,'Dados Mensais (Histórico)'!$E$5:$E$521,$A8)=0,"",SUMIFS('Dados Mensais (Histórico)'!$J$5:$J$521,'Dados Mensais (Histórico)'!$B$5:$B$521,C$5,'Dados Mensais (Histórico)'!$E$5:$E$521,$A8)) | D8: =IF(COUNTIFS('Dados Mensais (Histórico)'!$B$5:$B$521,D$5,'Dados Mensais (Histórico)'!$E$5:$E$521,$A8)=0,"",SUMIFS('Dados Mensais (Histórico)'!$J$5:$J$521,'Dados Mensais (Histórico)'!$B$5:$B$521,D$5,'Dados Mensais (Histórico)'!$E$5:$E$521,$A8)) -> 3585 | E8: =IF(COUNTIFS('Dados Mensais (Histórico)'!$B$5:$B$521,E$5,'Dados Mensais (Histórico)'!$E$5:$E$521,$A8)=0,"",SUMIFS('Dados Mensais (Histórico)'!$J$5:$J$521,'Dados Mensais (Histórico)'!$B$5:$B$521,E$5,'Dados Mensais (Histórico)'!$E$5:$E$521,$A8)) -> 3334 | F8: =IF(COUNTIFS('Dados Mensais (Histórico)'!$B$5:$B$521,F$5,'Dados Mensais (Histórico)'!$E$5:$E$521,$A8)=0,"",SUMIFS('Dados Mensais (Histórico)'!$J$5:$J$521,'Dados Mensais (Histórico)'!$B$5:$B$521,F$5,'Dados Mensais (Histórico)'!$E$5:$E$521,$A8)) -> 3322 | H8: ='Preco (R$ x KWh)'!B27 -> 1.0347311 | I8: =H8*0.7 -> 0.72431177 | K8: =IF(B8="","",ROUND(B8*$I8,2)) -> 2480.77 | L8: =IF(C8="","",ROUND(C8*$I8,2)) | M8: =IF(D8="","",ROUND(D8*$I8,2)) -> 2596.66 | N8: =IF(E8="","",ROUND(E8*$I8,2)) -> 2414.86 | O8: =IF(F8="","",ROUND(F8*$I8,2)) -> 2406.16 | P8: =SUM(K8:O8) -> 9898.45 | R8: Descrição | S8: ALUGUEL DE SISTEMA FOTO VOLTAICO - COD. CLIENTE 7030102643 (TRI STAR ENERBRAS ONE SCP)
A9: =EDATE(A8,1) -> 46266 | B9: =IF(COUNTIFS('Dados Mensais (Histórico)'!$B$5:$B$521,B$5,'Dados Mensais (Histórico)'!$E$5:$E$521,$A9)=0,"",SUMIFS('Dados Mensais (Histórico)'!$J$5:$J$521,'Dados Mensais (Histórico)'!$B$5:$B$521,B$5,'Dados Mensais (Histórico)'!$E$5:$E$521,$A9)) -> 4699 | C9: =IF(COUNTIFS('Dados Mensais (Histórico)'!$B$5:$B$521,C$5,'Dados Mensais (Histórico)'!$E$5:$E$521,$A9)=0,"",SUMIFS('Dados Mensais (Histórico)'!$J$5:$J$521,'Dados Mensais (Histórico)'!$B$5:$B$521,C$5,'Dados Mensais (Histórico)'!$E$5:$E$521,$A9)) | D9: =IF(COUNTIFS('Dados Mensais (Histórico)'!$B$5:$B$521,D$5,'Dados Mensais (Histórico)'!$E$5:$E$521,$A9)=0,"",SUMIFS('Dados Mensais (Histórico)'!$J$5:$J$521,'Dados Mensais (Histórico)'!$B$5:$B$521,D$5,'Dados Mensais (Histórico)'!$E$5:$E$521,$A9)) -> 4371 | E9: =IF(COUNTIFS('Dados Mensais (Histórico)'!$B$5:$B$521,E$5,'Dados Mensais (Histórico)'!$E$5:$E$521,$A9)=0,"",SUMIFS('Dados Mensais (Histórico)'!$J$5:$J$521,'Dados Mensais (Histórico)'!$B$5:$B$521,E$5,'Dados Mensais (Histórico)'!$E$5:$E$521,$A9)) -> 3223 | F9: =IF(COUNTIFS('Dados Mensais (Histórico)'!$B$5:$B$521,F$5,'Dados Mensais (Histórico)'!$E$5:$E$521,$A9)=0,"",SUMIFS('Dados Mensais (Histórico)'!$J$5:$J$521,'Dados Mensais (Histórico)'!$B$5:$B$521,F$5,'Dados Mensais (Histórico)'!$E$5:$E$521,$A9)) -> 5152 | H9: ='Preco (R$ x KWh)'!B28 -> 1.0448766 | I9: =H9*0.7 -> 0.73141363 | K9: =IF(B9="","",ROUND(B9*$I9,2)) -> 3436.91 | L9: =IF(C9="","",ROUND(C9*$I9,2)) | M9: =IF(D9="","",ROUND(D9*$I9,2)) -> 3197.01 | N9: =IF(E9="","",ROUND(E9*$I9,2)) -> 2357.35 | O9: =IF(F9="","",ROUND(F9*$I9,2)) -> 3768.24 | P9: =SUM(K9:O9) -> 12759.51 | R9: Doc Referencia | S9: COMP. 10/2026 - ENERGIA INJETADA: 338 kWh. Preço da energia (TUSD + TE) injetada sem o desconto: R$ 1,02847597/kWh
A10: =EDATE(A9,1) -> 46296 | B10: =IF(COUNTIFS('Dados Mensais (Histórico)'!$B$5:$B$521,B$5,'Dados Mensais (Histórico)'!$E$5:$E$521,$A10)=0,"",SUMIFS('Dados Mensais (Histórico)'!$J$5:$J$521,'Dados Mensais (Histórico)'!$B$5:$B$521,B$5,'Dados Mensais (Histórico)'!$E$5:$E$521,$A10)) -> 4368 | C10: =IF(COUNTIFS('Dados Mensais (Histórico)'!$B$5:$B$521,C$5,'Dados Mensais (Histórico)'!$E$5:$E$521,$A10)=0,"",SUMIFS('Dados Mensais (Histórico)'!$J$5:$J$521,'Dados Mensais (Histórico)'!$B$5:$B$521,C$5,'Dados Mensais (Histórico)'!$E$5:$E$521,$A10)) -> 3633 | D10: =IF(COUNTIFS('Dados Mensais (Histórico)'!$B$5:$B$521,D$5,'Dados Mensais (Histórico)'!$E$5:$E$521,$A10)=0,"",SUMIFS('Dados Mensais (Histórico)'!$J$5:$J$521,'Dados Mensais (Histórico)'!$B$5:$B$521,D$5,'Dados Mensais (Histórico)'!$E$5:$E$521,$A10)) -> 6327 | E10: =IF(COUNTIFS('Dados Mensais (Histórico)'!$B$5:$B$521,E$5,'Dados Mensais (Histórico)'!$E$5:$E$521,$A10)=0,"",SUMIFS('Dados Mensais (Histórico)'!$J$5:$J$521,'Dados Mensais (Histórico)'!$B$5:$B$521,E$5,'Dados Mensais (Histórico)'!$E$5:$E$521,$A10)) | F10: =IF(COUNTIFS('Dados Mensais (Histórico)'!$B$5:$B$521,F$5,'Dados Mensais (Histórico)'!$E$5:$E$521,$A10)=0,"",SUMIFS('Dados Mensais (Histórico)'!$J$5:$J$521,'Dados Mensais (Histórico)'!$B$5:$B$521,F$5,'Dados Mensais (Histórico)'!$E$5:$E$521,$A10)) -> 10133 | H10: ='Preco (R$ x KWh)'!B29 -> 1.028476 | I10: =H10*0.7 -> 0.71993318 | K10: =IF(B10="","",ROUND(B10*$I10,2)) -> 3144.67 | L10: =IF(C10="","",ROUND(C10*$I10,2)) -> 2615.52 | M10: =IF(D10="","",ROUND(D10*$I10,2)) -> 4555.02 | N10: =IF(E10="","",ROUND(E10*$I10,2)) | O10: =IF(F10="","",ROUND(F10*$I10,2)) -> 7295.08 | P10: =SUM(K10:O10) -> 17610.29 | R10: Info Comple | S10: O valor cobrado já está com desconto de 30% previsto em contrato.
A11: =EDATE(A10,1) -> 46327 | B11: =IF(COUNTIFS('Dados Mensais (Histórico)'!$B$5:$B$521,B$5,'Dados Mensais (Histórico)'!$E$5:$E$521,$A11)=0,"",SUMIFS('Dados Mensais (Histórico)'!$J$5:$J$521,'Dados Mensais (Histórico)'!$B$5:$B$521,B$5,'Dados Mensais (Histórico)'!$E$5:$E$521,$A11)) | C11: =IF(COUNTIFS('Dados Mensais (Histórico)'!$B$5:$B$521,C$5,'Dados Mensais (Histórico)'!$E$5:$E$521,$A11)=0,"",SUMIFS('Dados Mensais (Histórico)'!$J$5:$J$521,'Dados Mensais (Histórico)'!$B$5:$B$521,C$5,'Dados Mensais (Histórico)'!$E$5:$E$521,$A11)) | D11: =IF(COUNTIFS('Dados Mensais (Histórico)'!$B$5:$B$521,D$5,'Dados Mensais (Histórico)'!$E$5:$E$521,$A11)=0,"",SUMIFS('Dados Mensais (Histórico)'!$J$5:$J$521,'Dados Mensais (Histórico)'!$B$5:$B$521,D$5,'Dados Mensais (Histórico)'!$E$5:$E$521,$A11)) | E11: =IF(COUNTIFS('Dados Mensais (Histórico)'!$B$5:$B$521,E$5,'Dados Mensais (Histórico)'!$E$5:$E$521,$A11)=0,"",SUMIFS('Dados Mensais (Histórico)'!$J$5:$J$521,'Dados Mensais (Histórico)'!$B$5:$B$521,E$5,'Dados Mensais (Histórico)'!$E$5:$E$521,$A11)) | F11: =IF(COUNTIFS('Dados Mensais (Histórico)'!$B$5:$B$521,F$5,'Dados Mensais (Histórico)'!$E$5:$E$521,$A11)=0,"",SUMIFS('Dados Mensais (Histórico)'!$J$5:$J$521,'Dados Mensais (Histórico)'!$B$5:$B$521,F$5,'Dados Mensais (Histórico)'!$E$5:$E$521,$A11)) | H11: ='Preco (R$ x KWh)'!B30 -> 0 | I11: =H11*0.7 -> 0 | K11: =IF(B11="","",ROUND(B11*$I11,2)) | L11: =IF(C11="","",ROUND(C11*$I11,2)) | M11: =IF(D11="","",ROUND(D11*$I11,2)) | N11: =IF(E11="","",ROUND(E11*$I11,2)) | O11: =IF(F11="","",ROUND(F11*$I11,2)) | P11: =SUM(K11:O11) -> 0
A12: =EDATE(A11,1) -> 46357 | B12: =IF(COUNTIFS('Dados Mensais (Histórico)'!$B$5:$B$521,B$5,'Dados Mensais (Histórico)'!$E$5:$E$521,$A12)=0,"",SUMIFS('Dados Mensais (Histórico)'!$J$5:$J$521,'Dados Mensais (Histórico)'!$B$5:$B$521,B$5,'Dados Mensais (Histórico)'!$E$5:$E$521,$A12)) | C12: =IF(COUNTIFS('Dados Mensais (Histórico)'!$B$5:$B$521,C$5,'Dados Mensais (Histórico)'!$E$5:$E$521,$A12)=0,"",SUMIFS('Dados Mensais (Histórico)'!$J$5:$J$521,'Dados Mensais (Histórico)'!$B$5:$B$521,C$5,'Dados Mensais (Histórico)'!$E$5:$E$521,$A12)) | D12: =IF(COUNTIFS('Dados Mensais (Histórico)'!$B$5:$B$521,D$5,'Dados Mensais (Histórico)'!$E$5:$E$521,$A12)=0,"",SUMIFS('Dados Mensais (Histórico)'!$J$5:$J$521,'Dados Mensais (Histórico)'!$B$5:$B$521,D$5,'Dados Mensais (Histórico)'!$E$5:$E$521,$A12)) | E12: =IF(COUNTIFS('Dados Mensais (Histórico)'!$B$5:$B$521,E$5,'Dados Mensais (Histórico)'!$E$5:$E$521,$A12)=0,"",SUMIFS('Dados Mensais (Histórico)'!$J$5:$J$521,'Dados Mensais (Histórico)'!$B$5:$B$521,E$5,'Dados Mensais (Histórico)'!$E$5:$E$521,$A12)) | F12: =IF(COUNTIFS('Dados Mensais (Histórico)'!$B$5:$B$521,F$5,'Dados Mensais (Histórico)'!$E$5:$E$521,$A12)=0,"",SUMIFS('Dados Mensais (Histórico)'!$J$5:$J$521,'Dados Mensais (Histórico)'!$B$5:$B$521,F$5,'Dados Mensais (Histórico)'!$E$5:$E$521,$A12)) | H12: ='Preco (R$ x KWh)'!B31 -> 0 | I12: =H12*0.7 -> 0 | K12: =IF(B12="","",ROUND(B12*$I12,2)) | L12: =IF(C12="","",ROUND(C12*$I12,2)) | M12: =IF(D12="","",ROUND(D12*$I12,2)) | N12: =IF(E12="","",ROUND(E12*$I12,2)) | O12: =IF(F12="","",ROUND(F12*$I12,2)) | P12: =SUM(K12:O12) -> 0
A13: =EDATE(A12,1) -> 46388 | B13: =IF(COUNTIFS('Dados Mensais (Histórico)'!$B$5:$B$521,B$5,'Dados Mensais (Histórico)'!$E$5:$E$521,$A13)=0,"",SUMIFS('Dados Mensais (Histórico)'!$J$5:$J$521,'Dados Mensais (Histórico)'!$B$5:$B$521,B$5,'Dados Mensais (Histórico)'!$E$5:$E$521,$A13)) | C13: =IF(COUNTIFS('Dados Mensais (Histórico)'!$B$5:$B$521,C$5,'Dados Mensais (Histórico)'!$E$5:$E$521,$A13)=0,"",SUMIFS('Dados Mensais (Histórico)'!$J$5:$J$521,'Dados Mensais (Histórico)'!$B$5:$B$521,C$5,'Dados Mensais (Histórico)'!$E$5:$E$521,$A13)) | D13: =IF(COUNTIFS('Dados Mensais (Histórico)'!$B$5:$B$521,D$5,'Dados Mensais (Histórico)'!$E$5:$E$521,$A13)=0,"",SUMIFS('Dados Mensais (Histórico)'!$J$5:$J$521,'Dados Mensais (Histórico)'!$B$5:$B$521,D$5,'Dados Mensais (Histórico)'!$E$5:$E$521,$A13)) | E13: =IF(COUNTIFS('Dados Mensais (Histórico)'!$B$5:$B$521,E$5,'Dados Mensais (Histórico)'!$E$5:$E$521,$A13)=0,"",SUMIFS('Dados Mensais (Histórico)'!$J$5:$J$521,'Dados Mensais (Histórico)'!$B$5:$B$521,E$5,'Dados Mensais (Histórico)'!$E$5:$E$521,$A13)) | F13: =IF(COUNTIFS('Dados Mensais (Histórico)'!$B$5:$B$521,F$5,'Dados Mensais (Histórico)'!$E$5:$E$521,$A13)=0,"",SUMIFS('Dados Mensais (Histórico)'!$J$5:$J$521,'Dados Mensais (Histórico)'!$B$5:$B$521,F$5,'Dados Mensais (Histórico)'!$E$5:$E$521,$A13)) | H13: ='Preco (R$ x KWh)'!B32 -> 0 | I13: =H13*0.7 -> 0 | K13: =IF(B13="","",ROUND(B13*$I13,2)) | L13: =IF(C13="","",ROUND(C13*$I13,2)) | M13: =IF(D13="","",ROUND(D13*$I13,2)) | N13: =IF(E13="","",ROUND(E13*$I13,2)) | O13: =IF(F13="","",ROUND(F13*$I13,2)) | P13: =SUM(K13:O13) -> 0
A14: =EDATE(A13,1) -> 46419 | B14: =IF(COUNTIFS('Dados Mensais (Histórico)'!$B$5:$B$521,B$5,'Dados Mensais (Histórico)'!$E$5:$E$521,$A14)=0,"",SUMIFS('Dados Mensais (Histórico)'!$J$5:$J$521,'Dados Mensais (Histórico)'!$B$5:$B$521,B$5,'Dados Mensais (Histórico)'!$E$5:$E$521,$A14)) | C14: =IF(COUNTIFS('Dados Mensais (Histórico)'!$B$5:$B$521,C$5,'Dados Mensais (Histórico)'!$E$5:$E$521,$A14)=0,"",SUMIFS('Dados Mensais (Histórico)'!$J$5:$J$521,'Dados Mensais (Histórico)'!$B$5:$B$521,C$5,'Dados Mensais (Histórico)'!$E$5:$E$521,$A14)) | D14: =IF(COUNTIFS('Dados Mensais (Histórico)'!$B$5:$B$521,D$5,'Dados Mensais (Histórico)'!$E$5:$E$521,$A14)=0,"",SUMIFS('Dados Mensais (Histórico)'!$J$5:$J$521,'Dados Mensais (Histórico)'!$B$5:$B$521,D$5,'Dados Mensais (Histórico)'!$E$5:$E$521,$A14)) | E14: =IF(COUNTIFS('Dados Mensais (Histórico)'!$B$5:$B$521,E$5,'Dados Mensais (Histórico)'!$E$5:$E$521,$A14)=0,"",SUMIFS('Dados Mensais (Histórico)'!$J$5:$J$521,'Dados Mensais (Histórico)'!$B$5:$B$521,E$5,'Dados Mensais (Histórico)'!$E$5:$E$521,$A14)) | F14: =IF(COUNTIFS('Dados Mensais (Histórico)'!$B$5:$B$521,F$5,'Dados Mensais (Histórico)'!$E$5:$E$521,$A14)=0,"",SUMIFS('Dados Mensais (Histórico)'!$J$5:$J$521,'Dados Mensais (Histórico)'!$B$5:$B$521,F$5,'Dados Mensais (Histórico)'!$E$5:$E$521,$A14)) | H14: ='Preco (R$ x KWh)'!B33 -> 0 | I14: =H14*0.7 -> 0 | K14: =IF(B14="","",ROUND(B14*$I14,2)) | L14: =IF(C14="","",ROUND(C14*$I14,2)) | M14: =IF(D14="","",ROUND(D14*$I14,2)) | N14: =IF(E14="","",ROUND(E14*$I14,2)) | O14: =IF(F14="","",ROUND(F14*$I14,2)) | P14: =SUM(K14:O14) -> 0
A15: =EDATE(A14,1) -> 46447 | B15: =IF(COUNTIFS('Dados Mensais (Histórico)'!$B$5:$B$521,B$5,'Dados Mensais (Histórico)'!$E$5:$E$521,$A15)=0,"",SUMIFS('Dados Mensais (Histórico)'!$J$5:$J$521,'Dados Mensais (Histórico)'!$B$5:$B$521,B$5,'Dados Mensais (Histórico)'!$E$5:$E$521,$A15)) | C15: =IF(COUNTIFS('Dados Mensais (Histórico)'!$B$5:$B$521,C$5,'Dados Mensais (Histórico)'!$E$5:$E$521,$A15)=0,"",SUMIFS('Dados Mensais (Histórico)'!$J$5:$J$521,'Dados Mensais (Histórico)'!$B$5:$B$521,C$5,'Dados Mensais (Histórico)'!$E$5:$E$521,$A15)) | D15: =IF(COUNTIFS('Dados Mensais (Histórico)'!$B$5:$B$521,D$5,'Dados Mensais (Histórico)'!$E$5:$E$521,$A15)=0,"",SUMIFS('Dados Mensais (Histórico)'!$J$5:$J$521,'Dados Mensais (Histórico)'!$B$5:$B$521,D$5,'Dados Mensais (Histórico)'!$E$5:$E$521,$A15)) | E15: =IF(COUNTIFS('Dados Mensais (Histórico)'!$B$5:$B$521,E$5,'Dados Mensais (Histórico)'!$E$5:$E$521,$A15)=0,"",SUMIFS('Dados Mensais (Histórico)'!$J$5:$J$521,'Dados Mensais (Histórico)'!$B$5:$B$521,E$5,'Dados Mensais (Histórico)'!$E$5:$E$521,$A15)) | F15: =IF(COUNTIFS('Dados Mensais (Histórico)'!$B$5:$B$521,F$5,'Dados Mensais (Histórico)'!$E$5:$E$521,$A15)=0,"",SUMIFS('Dados Mensais (Histórico)'!$J$5:$J$521,'Dados Mensais (Histórico)'!$B$5:$B$521,F$5,'Dados Mensais (Histórico)'!$E$5:$E$521,$A15)) | H15: ='Preco (R$ x KWh)'!B34 -> 0 | I15: =H15*0.7 -> 0 | K15: =IF(B15="","",ROUND(B15*$I15,2)) | L15: =IF(C15="","",ROUND(C15*$I15,2)) | M15: =IF(D15="","",ROUND(D15*$I15,2)) | N15: =IF(E15="","",ROUND(E15*$I15,2)) | O15: =IF(F15="","",ROUND(F15*$I15,2)) | P15: =SUM(K15:O15) -> 0
A16: =EDATE(A15,1) -> 46478 | B16: =IF(COUNTIFS('Dados Mensais (Histórico)'!$B$5:$B$521,B$5,'Dados Mensais (Histórico)'!$E$5:$E$521,$A16)=0,"",SUMIFS('Dados Mensais (Histórico)'!$J$5:$J$521,'Dados Mensais (Histórico)'!$B$5:$B$521,B$5,'Dados Mensais (Histórico)'!$E$5:$E$521,$A16)) | C16: =IF(COUNTIFS('Dados Mensais (Histórico)'!$B$5:$B$521,C$5,'Dados Mensais (Histórico)'!$E$5:$E$521,$A16)=0,"",SUMIFS('Dados Mensais (Histórico)'!$J$5:$J$521,'Dados Mensais (Histórico)'!$B$5:$B$521,C$5,'Dados Mensais (Histórico)'!$E$5:$E$521,$A16)) | D16: =IF(COUNTIFS('Dados Mensais (Histórico)'!$B$5:$B$521,D$5,'Dados Mensais (Histórico)'!$E$5:$E$521,$A16)=0,"",SUMIFS('Dados Mensais (Histórico)'!$J$5:$J$521,'Dados Mensais (Histórico)'!$B$5:$B$521,D$5,'Dados Mensais (Histórico)'!$E$5:$E$521,$A16)) | E16: =IF(COUNTIFS('Dados Mensais (Histórico)'!$B$5:$B$521,E$5,'Dados Mensais (Histórico)'!$E$5:$E$521,$A16)=0,"",SUMIFS('Dados Mensais (Histórico)'!$J$5:$J$521,'Dados Mensais (Histórico)'!$B$5:$B$521,E$5,'Dados Mensais (Histórico)'!$E$5:$E$521,$A16)) | F16: =IF(COUNTIFS('Dados Mensais (Histórico)'!$B$5:$B$521,F$5,'Dados Mensais (Histórico)'!$E$5:$E$521,$A16)=0,"",SUMIFS('Dados Mensais (Histórico)'!$J$5:$J$521,'Dados Mensais (Histórico)'!$B$5:$B$521,F$5,'Dados Mensais (Histórico)'!$E$5:$E$521,$A16)) | H16: ='Preco (R$ x KWh)'!B35 -> 0 | I16: =H16*0.7 -> 0 | K16: =IF(B16="","",ROUND(B16*$I16,2)) | L16: =IF(C16="","",ROUND(C16*$I16,2)) | M16: =IF(D16="","",ROUND(D16*$I16,2)) | N16: =IF(E16="","",ROUND(E16*$I16,2)) | O16: =IF(F16="","",ROUND(F16*$I16,2)) | P16: =SUM(K16:O16) -> 0
A17: =EDATE(A16,1) -> 46508 | B17: =IF(COUNTIFS('Dados Mensais (Histórico)'!$B$5:$B$521,B$5,'Dados Mensais (Histórico)'!$E$5:$E$521,$A17)=0,"",SUMIFS('Dados Mensais (Histórico)'!$J$5:$J$521,'Dados Mensais (Histórico)'!$B$5:$B$521,B$5,'Dados Mensais (Histórico)'!$E$5:$E$521,$A17)) | C17: =IF(COUNTIFS('Dados Mensais (Histórico)'!$B$5:$B$521,C$5,'Dados Mensais (Histórico)'!$E$5:$E$521,$A17)=0,"",SUMIFS('Dados Mensais (Histórico)'!$J$5:$J$521,'Dados Mensais (Histórico)'!$B$5:$B$521,C$5,'Dados Mensais (Histórico)'!$E$5:$E$521,$A17)) | D17: =IF(COUNTIFS('Dados Mensais (Histórico)'!$B$5:$B$521,D$5,'Dados Mensais (Histórico)'!$E$5:$E$521,$A17)=0,"",SUMIFS('Dados Mensais (Histórico)'!$J$5:$J$521,'Dados Mensais (Histórico)'!$B$5:$B$521,D$5,'Dados Mensais (Histórico)'!$E$5:$E$521,$A17)) | E17: =IF(COUNTIFS('Dados Mensais (Histórico)'!$B$5:$B$521,E$5,'Dados Mensais (Histórico)'!$E$5:$E$521,$A17)=0,"",SUMIFS('Dados Mensais (Histórico)'!$J$5:$J$521,'Dados Mensais (Histórico)'!$B$5:$B$521,E$5,'Dados Mensais (Histórico)'!$E$5:$E$521,$A17)) | F17: =IF(COUNTIFS('Dados Mensais (Histórico)'!$B$5:$B$521,F$5,'Dados Mensais (Histórico)'!$E$5:$E$521,$A17)=0,"",SUMIFS('Dados Mensais (Histórico)'!$J$5:$J$521,'Dados Mensais (Histórico)'!$B$5:$B$521,F$5,'Dados Mensais (Histórico)'!$E$5:$E$521,$A17)) | H17: ='Preco (R$ x KWh)'!B36 -> 0 | I17: =H17*0.7 -> 0 | K17: =IF(B17="","",ROUND(B17*$I17,2)) | L17: =IF(C17="","",ROUND(C17*$I17,2)) | M17: =IF(D17="","",ROUND(D17*$I17,2)) | N17: =IF(E17="","",ROUND(E17*$I17,2)) | O17: =IF(F17="","",ROUND(F17*$I17,2)) | P17: =SUM(K17:O17) -> 0
A18: =EDATE(A17,1) -> 46539 | B18: =IF(COUNTIFS('Dados Mensais (Histórico)'!$B$5:$B$521,B$5,'Dados Mensais (Histórico)'!$E$5:$E$521,$A18)=0,"",SUMIFS('Dados Mensais (Histórico)'!$J$5:$J$521,'Dados Mensais (Histórico)'!$B$5:$B$521,B$5,'Dados Mensais (Histórico)'!$E$5:$E$521,$A18)) | C18: =IF(COUNTIFS('Dados Mensais (Histórico)'!$B$5:$B$521,C$5,'Dados Mensais (Histórico)'!$E$5:$E$521,$A18)=0,"",SUMIFS('Dados Mensais (Histórico)'!$J$5:$J$521,'Dados Mensais (Histórico)'!$B$5:$B$521,C$5,'Dados Mensais (Histórico)'!$E$5:$E$521,$A18)) | D18: =IF(COUNTIFS('Dados Mensais (Histórico)'!$B$5:$B$521,D$5,'Dados Mensais (Histórico)'!$E$5:$E$521,$A18)=0,"",SUMIFS('Dados Mensais (Histórico)'!$J$5:$J$521,'Dados Mensais (Histórico)'!$B$5:$B$521,D$5,'Dados Mensais (Histórico)'!$E$5:$E$521,$A18)) | E18: =IF(COUNTIFS('Dados Mensais (Histórico)'!$B$5:$B$521,E$5,'Dados Mensais (Histórico)'!$E$5:$E$521,$A18)=0,"",SUMIFS('Dados Mensais (Histórico)'!$J$5:$J$521,'Dados Mensais (Histórico)'!$B$5:$B$521,E$5,'Dados Mensais (Histórico)'!$E$5:$E$521,$A18)) | F18: =IF(COUNTIFS('Dados Mensais (Histórico)'!$B$5:$B$521,F$5,'Dados Mensais (Histórico)'!$E$5:$E$521,$A18)=0,"",SUMIFS('Dados Mensais (Histórico)'!$J$5:$J$521,'Dados Mensais (Histórico)'!$B$5:$B$521,F$5,'Dados Mensais (Histórico)'!$E$5:$E$521,$A18)) | H18: ='Preco (R$ x KWh)'!B37 -> 0 | I18: =H18*0.7 -> 0 | K18: =IF(B18="","",ROUND(B18*$I18,2)) | L18: =IF(C18="","",ROUND(C18*$I18,2)) | M18: =IF(D18="","",ROUND(D18*$I18,2)) | N18: =IF(E18="","",ROUND(E18*$I18,2)) | O18: =IF(F18="","",ROUND(F18*$I18,2)) | P18: =SUM(K18:O18) -> 0
A19: =EDATE(A18,1) -> 46569 | B19: =IF(COUNTIFS('Dados Mensais (Histórico)'!$B$5:$B$521,B$5,'Dados Mensais (Histórico)'!$E$5:$E$521,$A19)=0,"",SUMIFS('Dados Mensais (Histórico)'!$J$5:$J$521,'Dados Mensais (Histórico)'!$B$5:$B$521,B$5,'Dados Mensais (Histórico)'!$E$5:$E$521,$A19)) | C19: =IF(COUNTIFS('Dados Mensais (Histórico)'!$B$5:$B$521,C$5,'Dados Mensais (Histórico)'!$E$5:$E$521,$A19)=0,"",SUMIFS('Dados Mensais (Histórico)'!$J$5:$J$521,'Dados Mensais (Histórico)'!$B$5:$B$521,C$5,'Dados Mensais (Histórico)'!$E$5:$E$521,$A19)) | D19: =IF(COUNTIFS('Dados Mensais (Histórico)'!$B$5:$B$521,D$5,'Dados Mensais (Histórico)'!$E$5:$E$521,$A19)=0,"",SUMIFS('Dados Mensais (Histórico)'!$J$5:$J$521,'Dados Mensais (Histórico)'!$B$5:$B$521,D$5,'Dados Mensais (Histórico)'!$E$5:$E$521,$A19)) | E19: =IF(COUNTIFS('Dados Mensais (Histórico)'!$B$5:$B$521,E$5,'Dados Mensais (Histórico)'!$E$5:$E$521,$A19)=0,"",SUMIFS('Dados Mensais (Histórico)'!$J$5:$J$521,'Dados Mensais (Histórico)'!$B$5:$B$521,E$5,'Dados Mensais (Histórico)'!$E$5:$E$521,$A19)) | F19: =IF(COUNTIFS('Dados Mensais (Histórico)'!$B$5:$B$521,F$5,'Dados Mensais (Histórico)'!$E$5:$E$521,$A19)=0,"",SUMIFS('Dados Mensais (Histórico)'!$J$5:$J$521,'Dados Mensais (Histórico)'!$B$5:$B$521,F$5,'Dados Mensais (Histórico)'!$E$5:$E$521,$A19)) | H19: ='Preco (R$ x KWh)'!B38 -> 0 | I19: =H19*0.7 -> 0 | K19: =IF(B19="","",ROUND(B19*$I19,2)) | L19: =IF(C19="","",ROUND(C19*$I19,2)) | M19: =IF(D19="","",ROUND(D19*$I19,2)) | N19: =IF(E19="","",ROUND(E19*$I19,2)) | O19: =IF(F19="","",ROUND(F19*$I19,2)) | P19: =SUM(K19:O19) -> 0
A20: =EDATE(A19,1) -> 46600 | B20: =IF(COUNTIFS('Dados Mensais (Histórico)'!$B$5:$B$521,B$5,'Dados Mensais (Histórico)'!$E$5:$E$521,$A20)=0,"",SUMIFS('Dados Mensais (Histórico)'!$J$5:$J$521,'Dados Mensais (Histórico)'!$B$5:$B$521,B$5,'Dados Mensais (Histórico)'!$E$5:$E$521,$A20)) | C20: =IF(COUNTIFS('Dados Mensais (Histórico)'!$B$5:$B$521,C$5,'Dados Mensais (Histórico)'!$E$5:$E$521,$A20)=0,"",SUMIFS('Dados Mensais (Histórico)'!$J$5:$J$521,'Dados Mensais (Histórico)'!$B$5:$B$521,C$5,'Dados Mensais (Histórico)'!$E$5:$E$521,$A20)) | D20: =IF(COUNTIFS('Dados Mensais (Histórico)'!$B$5:$B$521,D$5,'Dados Mensais (Histórico)'!$E$5:$E$521,$A20)=0,"",SUMIFS('Dados Mensais (Histórico)'!$J$5:$J$521,'Dados Mensais (Histórico)'!$B$5:$B$521,D$5,'Dados Mensais (Histórico)'!$E$5:$E$521,$A20)) | E20: =IF(COUNTIFS('Dados Mensais (Histórico)'!$B$5:$B$521,E$5,'Dados Mensais (Histórico)'!$E$5:$E$521,$A20)=0,"",SUMIFS('Dados Mensais (Histórico)'!$J$5:$J$521,'Dados Mensais (Histórico)'!$B$5:$B$521,E$5,'Dados Mensais (Histórico)'!$E$5:$E$521,$A20)) | F20: =IF(COUNTIFS('Dados Mensais (Histórico)'!$B$5:$B$521,F$5,'Dados Mensais (Histórico)'!$E$5:$E$521,$A20)=0,"",SUMIFS('Dados Mensais (Histórico)'!$J$5:$J$521,'Dados Mensais (Histórico)'!$B$5:$B$521,F$5,'Dados Mensais (Histórico)'!$E$5:$E$521,$A20)) | H20: ='Preco (R$ x KWh)'!B39 -> 0 | I20: =H20*0.7 -> 0 | K20: =IF(B20="","",ROUND(B20*$I20,2)) | L20: =IF(C20="","",ROUND(C20*$I20,2)) | M20: =IF(D20="","",ROUND(D20*$I20,2)) | N20: =IF(E20="","",ROUND(E20*$I20,2)) | O20: =IF(F20="","",ROUND(F20*$I20,2)) | P20: =SUM(K20:O20) -> 0
A21: =EDATE(A20,1) -> 46631 | B21: =IF(COUNTIFS('Dados Mensais (Histórico)'!$B$5:$B$521,B$5,'Dados Mensais (Histórico)'!$E$5:$E$521,$A21)=0,"",SUMIFS('Dados Mensais (Histórico)'!$J$5:$J$521,'Dados Mensais (Histórico)'!$B$5:$B$521,B$5,'Dados Mensais (Histórico)'!$E$5:$E$521,$A21)) | C21: =IF(COUNTIFS('Dados Mensais (Histórico)'!$B$5:$B$521,C$5,'Dados Mensais (Histórico)'!$E$5:$E$521,$A21)=0,"",SUMIFS('Dados Mensais (Histórico)'!$J$5:$J$521,'Dados Mensais (Histórico)'!$B$5:$B$521,C$5,'Dados Mensais (Histórico)'!$E$5:$E$521,$A21)) | D21: =IF(COUNTIFS('Dados Mensais (Histórico)'!$B$5:$B$521,D$5,'Dados Mensais (Histórico)'!$E$5:$E$521,$A21)=0,"",SUMIFS('Dados Mensais (Histórico)'!$J$5:$J$521,'Dados Mensais (Histórico)'!$B$5:$B$521,D$5,'Dados Mensais (Histórico)'!$E$5:$E$521,$A21)) | E21: =IF(COUNTIFS('Dados Mensais (Histórico)'!$B$5:$B$521,E$5,'Dados Mensais (Histórico)'!$E$5:$E$521,$A21)=0,"",SUMIFS('Dados Mensais (Histórico)'!$J$5:$J$521,'Dados Mensais (Histórico)'!$B$5:$B$521,E$5,'Dados Mensais (Histórico)'!$E$5:$E$521,$A21)) | F21: =IF(COUNTIFS('Dados Mensais (Histórico)'!$B$5:$B$521,F$5,'Dados Mensais (Histórico)'!$E$5:$E$521,$A21)=0,"",SUMIFS('Dados Mensais (Histórico)'!$J$5:$J$521,'Dados Mensais (Histórico)'!$B$5:$B$521,F$5,'Dados Mensais (Histórico)'!$E$5:$E$521,$A21)) | H21: ='Preco (R$ x KWh)'!B40 -> 0 | I21: =H21*0.7 -> 0 | K21: =IF(B21="","",ROUND(B21*$I21,2)) | L21: =IF(C21="","",ROUND(C21*$I21,2)) | M21: =IF(D21="","",ROUND(D21*$I21,2)) | N21: =IF(E21="","",ROUND(E21*$I21,2)) | O21: =IF(F21="","",ROUND(F21*$I21,2)) | P21: =SUM(K21:O21) -> 0
A22: =EDATE(A21,1) -> 46661 | B22: =IF(COUNTIFS('Dados Mensais (Histórico)'!$B$5:$B$521,B$5,'Dados Mensais (Histórico)'!$E$5:$E$521,$A22)=0,"",SUMIFS('Dados Mensais (Histórico)'!$J$5:$J$521,'Dados Mensais (Histórico)'!$B$5:$B$521,B$5,'Dados Mensais (Histórico)'!$E$5:$E$521,$A22)) | C22: =IF(COUNTIFS('Dados Mensais (Histórico)'!$B$5:$B$521,C$5,'Dados Mensais (Histórico)'!$E$5:$E$521,$A22)=0,"",SUMIFS('Dados Mensais (Histórico)'!$J$5:$J$521,'Dados Mensais (Histórico)'!$B$5:$B$521,C$5,'Dados Mensais (Histórico)'!$E$5:$E$521,$A22)) | D22: =IF(COUNTIFS('Dados Mensais (Histórico)'!$B$5:$B$521,D$5,'Dados Mensais (Histórico)'!$E$5:$E$521,$A22)=0,"",SUMIFS('Dados Mensais (Histórico)'!$J$5:$J$521,'Dados Mensais (Histórico)'!$B$5:$B$521,D$5,'Dados Mensais (Histórico)'!$E$5:$E$521,$A22)) | E22: =IF(COUNTIFS('Dados Mensais (Histórico)'!$B$5:$B$521,E$5,'Dados Mensais (Histórico)'!$E$5:$E$521,$A22)=0,"",SUMIFS('Dados Mensais (Histórico)'!$J$5:$J$521,'Dados Mensais (Histórico)'!$B$5:$B$521,E$5,'Dados Mensais (Histórico)'!$E$5:$E$521,$A22)) | F22: =IF(COUNTIFS('Dados Mensais (Histórico)'!$B$5:$B$521,F$5,'Dados Mensais (Histórico)'!$E$5:$E$521,$A22)=0,"",SUMIFS('Dados Mensais (Histórico)'!$J$5:$J$521,'Dados Mensais (Histórico)'!$B$5:$B$521,F$5,'Dados Mensais (Histórico)'!$E$5:$E$521,$A22)) | H22: ='Preco (R$ x KWh)'!B41 -> 0 | I22: =H22*0.7 -> 0 | K22: =IF(B22="","",ROUND(B22*$I22,2)) | L22: =IF(C22="","",ROUND(C22*$I22,2)) | M22: =IF(D22="","",ROUND(D22*$I22,2)) | N22: =IF(E22="","",ROUND(E22*$I22,2)) | O22: =IF(F22="","",ROUND(F22*$I22,2)) | P22: =SUM(K22:O22) -> 0
... A42: =EDATE(A41,1) -> 47270 | B42: =IF(COUNTIFS('Dados Mensais (Histórico)'!$B$5:$B$521,B$5,'Dados Mensais (Histórico)'!$E$5:$E$521,$A42)=0,"",SUMIFS('Dados Mensais (Histórico)'!$J$5:$J$521,'Dados Mensais (Histórico)'!$B$5:$B$521,B$5,'Dados Mensais (Histórico)'!$E$5:$E$521,$A42)) | C42: =IF(COUNTIFS('Dados Mensais (Histórico)'!$B$5:$B$521,C$5,'Dados Mensais (Histórico)'!$E$5:$E$521,$A42)=0,"",SUMIFS('Dados Mensais (Histórico)'!$J$5:$J$521,'Dados Mensais (Histórico)'!$B$5:$B$521,C$5,'Dados Mensais (Histórico)'!$E$5:$E$521,$A42)) | D42: =IF(COUNTIFS('Dados Mensais (Histórico)'!$B$5:$B$521,D$5,'Dados Mensais (Histórico)'!$E$5:$E$521,$A42)=0,"",SUMIFS('Dados Mensais (Histórico)'!$J$5:$J$521,'Dados Mensais (Histórico)'!$B$5:$B$521,D$5,'Dados Mensais (Histórico)'!$E$5:$E$521,$A42)) | E42: =IF(COUNTIFS('Dados Mensais (Histórico)'!$B$5:$B$521,E$5,'Dados Mensais (Histórico)'!$E$5:$E$521,$A42)=0,"",SUMIFS('Dados Mensais (Histórico)'!$J$5:$J$521,'Dados Mensais (Histórico)'!$B$5:$B$521,E$5,'Dados Mensais (Histórico)'!$E$5:$E$521,$A42)) | F42: =IF(COUNTIFS('Dados Mensais (Histórico)'!$B$5:$B$521,F$5,'Dados Mensais (Histórico)'!$E$5:$E$521,$A42)=0,"",SUMIFS('Dados Mensais (Histórico)'!$J$5:$J$521,'Dados Mensais (Histórico)'!$B$5:$B$521,F$5,'Dados Mensais (Histórico)'!$E$5:$E$521,$A42)) | H42: ='Preco (R$ x KWh)'!B61 -> 0 | I42: =H42*0.7 -> 0 | K42: =IF(B42="","",ROUND(B42*$I42,2)) | L42: =IF(C42="","",ROUND(C42*$I42,2)) | M42: =IF(D42="","",ROUND(D42*$I42,2)) | N42: =IF(E42="","",ROUND(E42*$I42,2)) | O42: =IF(F42="","",ROUND(F42*$I42,2)) | P42: =SUM(K42:O42) -> 0

Sheet Resumo Usinas (Histórico)
B1: Resumo Usinas — Histórico Mensal (TRI STAR ONE SCP)
B2: TABELA CUMULATIVA: a cada mês, adicione uma nova linha por usina com os dados do 'Resumo de Saldo de Crédito' do novo demonstrativo
A4: concatenar | B4: Usina / Cliente Gerador | C4: Código Cliente Injetor | D4: Unidade Consumidora | E4: Potência (kWp) | F4: Modalidade GD | G4: Classificação GD | H4: Competência | I4: Saldo anterior | J4: Total Injetado (kWh) | K4: Total Compensado (kWh) | L4: Saldo Acumulado (kWh) | M4: Próx. Saldo Acum. a Expirar (kWh) | N4: Ciclo de Faturamento a Expirar | O4: Total de Créditos Expirados (kWh)
A5: =CONCATENATE(C5,H5) -> 703010264346204 | B5: ARCO IRIS ADMINISTRADORA DE BENS E IMOVEIS LTDA | C5: 7030102643 | D5: 228590203276 | E5: 30 | F5: AR | G5: GDII | H5: 46204 | J5: 338 | K5: 0 | L5: 338 | M5: 338 | N5: 48030 | O5: 0
A6: =CONCATENATE(C6,H6) -> 703086904946204 | B6: SAF HOSPEDAGENS LTDA | C6: 7030869049 | D6: 233150603260 | E6: 33 | F6: CL | G6: GDII | H6: 46204 | J6: 875 | K6: 0 | L6: 875 | M6: 875 | N6: jul/2031 | O6: 0
A7: =CONCATENATE(C7,H7) -> 703086906546204 | B7: JM EMPREENDIMENTOS IMOBILIARIOS E HOTE | C7: 7030869065 | E7: 15 | F7: CL | G7: GDII | H7: 46204 | J7: 579 | K7: 0 | L7: 579 | M7: 579 | N7: jul/2031 | O7: 0
A8: =CONCATENATE(C8,H8) -> 703086929446204 | B8: SOMBRA FLORESTA EMPREENDIMENTOS IMOBILIARIOS LTDA | C8: 7030869294 | D8: 204708803230 | E8: 15 | F8: AR | G8: GDII | H8: 46204 | J8: 608 | K8: 0 | L8: 608 | M8: 608 | N8: jul/2031 | O8: 0
A9: =CONCATENATE(C9,H9) -> 703010264346235 | B9: ARCO IRIS ADMINISTRADORA DE BENS E IMOVEIS LTDA | C9: 7030102643 | D9: 228590203276 | E9: 30 | F9: AR | G9: GDII | H9: 46235 | J9: 3763 | K9: 0 | L9: 338 | M9: 11593.15 | N9: 47727 | O9: 0
A10: =CONCATENATE(C10,H10) -> 703086904946235 | B10: SAF HOSPEDAGENS LTDA | C10: 7030869049 | D10: 233150603260 | E10: 33 | F10: CL | G10: GDII | H10: 46235 | J10: 4460 | K10: 0 | L10: 4460 | M10: 875 | N10: jul/2031 | O10: 0
A11: =CONCATENATE(C11,H11) -> 703086906546235 | B11: JM EMPREENDIMENTOS IMOBILIARIOS E HOTE | C11: 7030869065 | E11: 15 | F11: AR | G11: GDII | H11: 46235 | J11: 3913 | K11: 2552 | L11: 1361 | M11: 579 | N11: jul/2031 | O11: 0
A12: =CONCATENATE(C12,H12) -> 703086929446235 | B12: SOMBRA FLORESTA EMPREENDIMENTOS IMOBILIARIOS LTDA | C12: 7030869294 | D12: 204708803230 | E12: 15 | F12: AR | G12: GDII | H12: 46235 | J12: 3930 | K12: 3711 | L12: 827 | M12: 608 | N12: jul/2031 | O12: 0
A13: =CONCATENATE(C13,H13) -> 703010264346266 | B13: ARCO IRIS ADMINISTRADORA DE BENS E IMOVEIS LTDA | C13: 7030102643 | D13: 228590203276 | E13: 30 | F13: AR | G13: GDII | H13: 46266 | J13: 8462 | K13: 0 | L13: 338 | M13: 11593.15 | N13: 47727 | O13: 0
A14: =CONCATENATE(C14,H14) -> 703086904946266 | B14: SAF HOSPEDAGENS LTDA | C14: 7030869049 | D14: 233150603260 | E14: 33 | F14: CL | G14: GDII | H14: 46266 | J14: 8831 | K14: 0 | L14: 8831 | M14: 875 | N14: jul/2031 | O14: 0
A15: =CONCATENATE(C15,H15) -> 703086929446266 | B15: SOMBRA FLORESTA EMPREENDIMENTOS IMOBILIARIOS LTDA | C15: 7030869294 | D15: 204708803230 | E15: 60 | F15: AR | G15: GDII | H15: 46266 | J15: 9082 | K15: 7958 | L15: 1732 | M15: 608 | N15: jul/2031 | O15: 0
A16: =CONCATENATE(C16,H16) -> 703086906546266 | B16: JM EMPREENDIMENTOS IMOBILIARIOS E HOTE | C16: 7030869065 | E16: 60 | F16: AR | G16: GDII | H16: 46266 | I16: 1361 | J16: 7136 | K16: 4503 | L16: 2633 | M16: 579 | N16: jul/2031 | O16: 0
A17: =CONCATENATE(C17,H17) -> 703175443146296 | B17: ARCO IRIS ADMINISTRADORA DE BENS E IMOVEIS LTDA | C17: 7031754431 | D17: 235633803274 | E17: 33 | F17: AR | G17: GDII | H17: 46296 | J17: 3633 | K17: 0 | L17: 3633 | M17: 338 | N17: 47665 | O17: 0
A18: =CONCATENATE(C18,H18) -> 703010264346296 | B18: ARCO IRIS ADMINISTRADORA DE BENS E IMOVEIS LTDA | C18: 7030102643 | D18: 228590203276 | E18: 60 | F18: AR | G18: GDII | H18: 46296 | J18: 4368 | K18: 0 | L18: 338 | M18: 11593.15 | N18: 47727 | O18: 0
A19: =CONCATENATE(C19,H19) -> 703086904946296 | B19: SAF HOSPEDAGENS LTDA | C19: 7030869049 | D19: 233150603260 | E19: 60 | F19: CL | G19: GDII | H19: 46296 | J19: 15158 | K19: 0 | L19: 15158 | M19: 875 | N19: jul/2031 | O19: 0
A20: =CONCATENATE(C20,H20) -> 703086929446296 | B20: SOMBRA FLORESTA EMPREENDIMENTOS IMOBILIARIOS LTDA | C20: 7030869294 | D20: 204708803230 | E20: 60 | F20: AR | G20: GDII | H20: 46296 | J20: 19215 | K20: 11431 | L20: 8392 | M20: 608 | N20: jul/2031 | O20: 0
A21: =CONCATENATE(C21,H21)
A22: =CONCATENATE(C22,H22)
B24: Como usar: a cada novo demonstrativo mensal, adicione uma NOVA LINHA por usina (não sobrescreva a anterior) com a Competência do mês e os valores do bloco 'Resumo de Saldo de Crédito' do relatório. As linhas em amarelo abaixo dos dados são um espaço reservado para os próximos meses — copie a formatação para baixo conforme for preenchendo (as fórmulas do Dashboard já cobrem até a linha 500, então não é necessário ajustar nada). O Dashboard sempre pega automaticamente a competência escolhida (ou mais recente) de cada usina.

Sheet Rateio de Crédito
A1: Rateio de Crédito por Unidade Beneficiária (Configuração)
A2: Percentual de energia injetada alocado a cada código de cliente — atualize aqui se o rateio contratual mudar
A4: Usina | B4: Código Cliente Injetor (Gerador) | C4: Código Cliente Beneficiário | D4: Unidade Consumidora | E4: Papel | F4: Percentual de Rateio | G4: Vigente desde | H4: Classificação GD | I4: Observação
A5: ARCO IRIS ADMINISTRADORA DE BENS E IMOVEIS LTDA | B5: 7030102643 | C5: 7030102643 | D5: 228590203276 | E5: Injetor (Gerador) | F5: 0 | G5: 46204 | H5: GDII | I5: Prioridade 0% — não retém crédito próprio
A6: ARCO IRIS ADMINISTRADORA DE BENS E IMOVEIS LTDA | B6: 7030102643 | C6: 7001017068 | E6: Beneficiário | F6: 1 | G6: 46204 | H6: GDII | I6: Sem consumo faturado em jul/2026 (último registro: out/2025)
A7: SAF HOSPEDAGENS LTDA | B7: 7030869049 | C7: 7030869049 | E7: Injetor e Beneficiário (autoconsumo) | F7: 1 | G7: 46204 | H7: GDII | I7: Retém 100% do próprio crédito
A8: JM EMPREENDIMENTOS IMOBILIARIOS E HOTE | B8: 7030869065 | C8: 7030869065 | D8: 218723703243 | E8: Injetor (Gerador) | F8: 0 | G8: 46235 | H8: GDII | I8: ATENCAO: demonstrativo ago/2026 mostra injetor com 0% de retencao propria (antes 100% autoconsumo, vigente ate jul/2026) e um NOVO codigo beneficiario 7031138749 com 100% no Resumo do Saldo de Credito por Unidade. Sem historico de consumo nos ultimos 13 meses para o novo codigo. CONFIRMAR mudanca de rateio com a distribuidora antes de considerar definitiva.
A9: JM EMPREENDIMENTOS IMOBILIARIOS E HOTE | B9: 7030869065 | C9: 7031138749 | D9: 99953603243 | E9: Beneficiário | F9: 1 | G9: 46235 | I9: Novo codigo beneficiario identificado pela primeira vez no demonstrativo ago/2026 (Resumo do Saldo de Credito por Unidade), com 100% de rateio. Sem historico de consumo nos ultimos 13 meses (nao aparece na tabela de Dados dos Ultimos 13 Meses do relatorio) e saldo credito acumulado 0,00. Confirmar com a distribuidora se a unidade esta ativa antes de tratar como definitivo.
A10: SOMBRA FLORESTA EMPREENDIMENTOS IMOBILIARIOS LTDA | B10: 7030869294 | C10: 7030869294 | E10: Injetor (Gerador) | F10: 0 | G10: 46204 | H10: GDII | I10: Prioridade 0% — não retém crédito próprio
A11: SOMBRA FLORESTA EMPREENDIMENTOS IMOBILIARIOS LTDA | B11: 7030869294 | C11: 7022476844 | D11: 231291203225 | E11: Beneficiário | F11: 0.25 | G11: 46204 | H11: GDII
A12: SOMBRA FLORESTA EMPREENDIMENTOS IMOBILIARIOS LTDA | B12: 7030869294 | C12: 7022476950 | D12: 211634203208 | E12: Beneficiário | F12: 0.25 | G12: 46204 | H12: GDII
A13: SOMBRA FLORESTA EMPREENDIMENTOS IMOBILIARIOS LTDA | B13: 7030869294 | C13: 7022546729 | D13: 206313103215 | E13: Beneficiário | F13: 0.25 | G13: 46204 | H13: GDII
A14: SOMBRA FLORESTA EMPREENDIMENTOS IMOBILIARIOS LTDA | B14: 7030869294 | C14: 7022546796 | D14: 217456303200 | E14: Beneficiário | F14: 0.25 | G14: 46204 | H14: GDII
A15: ARCO IRIS ADMINISTRADORA DE BENS E IMOVEIS LTDA | B15: 7031754431 | C15: 7031754431 | D15: 235633803274 | E15: Injetor (Gerador) | F15: 0 | G15: 46296 | H15: GDII | I15: Prioridade 0% — não retém crédito próprio
A16: ARCO IRIS ADMINISTRADORA DE BENS E IMOVEIS LTDA | B16: 7031754431 | C16: 7027595701 | E16: Beneficiário | F16: 1 | G16: 46296 | H16: GDII
I17: Aguardando definição do rateio — usina em implantação
I18: Aguardando definição do rateio — usina em implantação
A22: Legenda de cores:
A23: Laranja = código injetor (gerador) puro, retém 0%
A24: Azul claro = injetor que também é 100% beneficiário (autoconsumo remoto)
A25: Verde = código beneficiário (recebe rateio de crédito)
A26: Amarelo = usina em construção, a preencher quando o rateio for definido

Sheet Dados Mensais (Histórico)
A1: Dados Mensais por Código de Cliente — Histórico
A2: TABELA CUMULATIVA: a cada mês, adicione uma nova linha por código de cliente (injetor e beneficiários) com os dados de consumo/injeção
A4: Usina | B4: Código Cliente | C4: Unidade Consumidora | D4: Papel | E4: Competência | F4: Posto Horário | G4: Saldo anterior | H4: Crédito Rec. De Outra UC Ger | I4: Energia Consumida (kWh) | J4: Energia Injetada (kWh) | K4: Energ. Exc. Alocada (kWh) | L4: KWH Compensado | M4: Energia Faturada (kWh) | N4: Crédito Transf. Outra UC | O4: Crédito (kWh) | P4: Classificação GD
A5: ARCO IRIS ADMINISTRADORA DE BENS E IMOVEIS LTDA | B5: 7030102643 | C5: 228590203276 | D5: Injetor | E5: 46204 | F5: TT | G5: 0 | H5: 0 | I5: 4 | J5: 338 | K5: 0 | L5: 0 | M5: 100 | N5: 0 | O5: 0 | P5: GDII
A6: ARCO IRIS ADMINISTRADORA DE BENS E IMOVEIS LTDA | B6: 7030102643 | C6: 228590203276 | D6: Injetor | E6: 46174 | F6: TT | G6: 0 | H6: 0 | I6: 6 | J6: 0 | K6: 0 | L6: 0 | M6: 6 | N6: 0 | O6: 0 | P6: GDII
A7: ARCO IRIS ADMINISTRADORA DE BENS E IMOVEIS LTDA | B7: 7001017068 | D7: Beneficiário | E7: 45931 | F7: TT | G7: 0 | H7: 0 | I7: 10248 | J7: 0 | K7: 0 | L7: 0 | M7: 0 | N7: 0 | O7: 0 | P7: GDII
A8: SAF HOSPEDAGENS LTDA | B8: 7030869049 | C8: 233150603260 | D8: Injetor/Beneficiário | E8: 46204 | F8: TT | G8: 0 | H8: 0 | I8: 0 | J8: 875 | K8: 875 | L8: 0 | M8: 100 | N8: 0 | O8: 875 | P8: GDII
A9: JM EMPREENDIMENTOS IMOBILIARIOS E HOTE | B9: 7030869065 | C9: 218723703243 | D9: Injetor/Beneficiário | E9: 46204 | F9: TT | G9: 0 | H9: 0 | I9: 0 | J9: 579 | K9: 579 | L9: 0 | M9: 100 | N9: 0 | O9: 579 | P9: GDII
A10: SOMBRA FLORESTA EMPREENDIMENTOS IMOBILIARIOS LTDA | B10: 7030869294 | C10: 204708803230 | D10: Injetor | E10: 46204 | F10: TT | G10: 0 | H10: 0 | I10: 0 | J10: 608 | K10: 0 | L10: 0 | M10: 100 | N10: 0 | O10: 0 | P10: GDII
A11: SOMBRA FLORESTA EMPREENDIMENTOS IMOBILIARIOS LTDA | B11: 7022476844 | C11: 231291203225 | D11: Beneficiário | E11: 46174 | F11: — | G11: 0 | H11: 0 | I11: 0 | J11: 0 | K11: 0 | L11: 0 | M11: 0 | N11: 0 | O11: 0 | P11: GDII
A12: SOMBRA FLORESTA EMPREENDIMENTOS IMOBILIARIOS LTDA | B12: 7022476950 | C12: 211634203208 | D12: Beneficiário | E12: 46174 | F12: — | G12: 0 | H12: 0 | I12: 0 | J12: 0 | K12: 0 | L12: 0 | M12: 0 | N12: 0 | O12: 0 | P12: GDII
A13: SOMBRA FLORESTA EMPREENDIMENTOS IMOBILIARIOS LTDA | B13: 7022546729 | C13: 206313103215 | D13: Beneficiário | E13: 46174 | F13: — | G13: 0 | H13: 0 | I13: 0 | J13: 0 | K13: 0 | L13: 0 | M13: 0 | N13: 0 | O13: 0 | P13: GDII
A14: SOMBRA FLORESTA EMPREENDIMENTOS IMOBILIARIOS LTDA | B14: 7022546796 | C14: 217456303200 | D14: Beneficiário | E14: 46174 | F14: — | G14: 0 | H14: 0 | I14: 0 | J14: 0 | K14: 0 | L14: 0 | M14: 0 | N14: 0 | O14: 0 | P14: GDII
A15: ARCO IRIS ADMINISTRADORA DE BENS E IMOVEIS LTDA | B15: 7030102643 | C15: 228590203276 | D15: Injetor | E15: 46235 | F15: TT | G15: 0 | H15: 0 | I15: 11 | J15: 3425 | K15: 0 | L15: 0 | M15: 100 | N15: 0 | O15: 0 | P15: GDII
A16: ARCO IRIS ADMINISTRADORA DE BENS E IMOVEIS LTDA | B16: 7001017068 | D16: Beneficiário | E16: 46204 | F16: TT | G16: 0 | H16: 2483.1 | I16: 10732 | J16: 0 | K16: 338 | L16: 2821.1 | M16: 7910.9 | N16: 0 | O16: 0 | P16: GDII
A17: SAF HOSPEDAGENS LTDA | B17: 7030869049 | C17: 233150603260 | D17: Injetor/Beneficiário | E17: 46235 | F17: TT | G17: 875 | H17: 0 | I17: 1 | J17: 3585 | K17: 3585 | L17: 0 | M17: 100 | N17: 0 | O17: 4460 | P17: GDII
A18: JM EMPREENDIMENTOS IMOBILIARIOS E HOTE | B18: 7030869065 | C18: 218723703243 | D18: Injetor/Beneficiário | E18: 46204 | F18: TT | G18: 0 | H18: 0 | I18: 0 | J18: 579 | K18: 579 | L18: 0 | M18: 100 | N18: 0 | O18: 579 | P18: GDII
A19: JM EMPREENDIMENTOS IMOBILIARIOS E HOTE | B19: 7030869065 | C19: 218723703243 | D19: Injetor/Beneficiário | E19: 46235 | F19: TT | G19: 579 | H19: 0 | I19: 6 | J19: 3334 | K19: 0 | L19: 0 | M19: 100 | N19: 0 | O19: 579 | P19: GDII
